Workbook

Sheet Summary
A1: Property | B1: Current | C1: Past | D1: Future | E1: Total
A2: 1127 Blackwell | B2: =COUNTIFS(Tenants!$C$2:$C$369,$A2,Tenants!$I$2:$I$369,B$1) -> 1 | C2: =COUNTIFS(Tenants!$C$2:$C$369,$A2,Tenants!$I$2:$I$369,C$1) -> 2 | D2: =COUNTIFS(Tenants!$C$2:$C$369,$A2,Tenants!$I$2:$I$369,D$1) -> 0 | E2: =SUM(B2:D2) -> 3
A3: 1700 Bradford House | B3: =COUNTIFS(Tenants!$C$2:$C$369,$A3,Tenants!$I$2:$I$369,B$1) -> 10 | C3: =COUNTIFS(Tenants!$C$2:$C$369,$A3,Tenants!$I$2:$I$369,C$1) -> 11 | D3: =COUNTIFS(Tenants!$C$2:$C$369,$A3,Tenants!$I$2:$I$369,D$1) -> 0 | E3: =SUM(B3:D3) -> 21
A4: 206 Shafor Street | B4: =COUNTIFS(Tenants!$C$2:$C$369,$A4,Tenants!$I$2:$I$369,B$1) -> 1 | C4: =COUNTIFS(Tenants!$C$2:$C$369,$A4,Tenants!$I$2:$I$369,C$1) -> 1 | D4: =COUNTIFS(Tenants!$C$2:$C$369,$A4,Tenants!$I$2:$I$369,D$1) -> 0 | E4: =SUM(B4:D4) -> 2
A5: 212 Hangar St. | B5: =COUNTIFS(Tenants!$C$2:$C$369,$A5,Tenants!$I$2:$I$369,B$1) -> 2 | C5: =COUNTIFS(Tenants!$C$2:$C$369,$A5,Tenants!$I$2:$I$369,C$1) -> 0 | D5: =COUNTIFS(Tenants!$C$2:$C$369,$A5,Tenants!$I$2:$I$369,D$1) -> 0 | E5: =SUM(B5:D5) -> 2
A6: 410-415 Southblock | B6: =COUNTIFS(Tenants!$C$2:$C$369,$A6,Tenants!$I$2:$I$369,B$1) -> 2 | C6: =COUNTIFS(Tenants!$C$2:$C$369,$A6,Tenants!$I$2:$I$369,C$1) -> 4 | D6: =COUNTIFS(Tenants!$C$2:$C$369,$A6,Tenants!$I$2:$I$369,D$1) -> 0 | E6: =SUM(B6:D6) -> 6
A7: Black Bear Mountains Campsite | B7: =COUNTIFS(Tenants!$C$2:$C$369,$A7,Tenants!$I$2:$I$369,B$1) -> 2 | C7: =COUNTIFS(Tenants!$C$2:$C$369,$A7,Tenants!$I$2:$I$369,C$1) -> 24 | D7: =COUNTIFS(Tenants!$C$2:$C$369,$A7,Tenants!$I$2:$I$369,D$1) -> 5 | E7: =SUM(B7:D7) -> 31
A8: Buckeye Hall | B8: =COUNTIFS(Tenants!$C$2:$C$369,$A8,Tenants!$I$2:$I$369,B$1) -> 14 | C8: =COUNTIFS(Tenants!$C$2:$C$369,$A8,Tenants!$I$2:$I$369,C$1) -> 39 | D8: =COUNTIFS(Tenants!$C$2:$C$369,$A8,Tenants!$I$2:$I$369,D$1) -> 0 | E8: =SUM(B8:D8) -> 53
A9: Clearcreek Condominiums | B9: =COUNTIFS(Tenants!$C$2:$C$369,$A9,Tenants!$I$2:$I$369,B$1) -> 29 | C9: =COUNTIFS(Tenants!$C$2:$C$369,$A9,Tenants!$I$2:$I$369,C$1) -> 16 | D9: =COUNTIFS(Tenants!$C$2:$C$369,$A9,Tenants!$I$2:$I$369,D$1) -> 0 | E9: =SUM(B9:D9) -> 45
A10: Corporate Business Park | B10: =COUNTIFS(Tenants!$C$2:$C$369,$A10,Tenants!$I$2:$I$369,B$1) -> 10 | C10: =COUNTIFS(Tenants!$C$2:$C$369,$A10,Tenants!$I$2:$I$369,C$1) -> 3 | D10: =COUNTIFS(Tenants!$C$2:$C$369,$A10,Tenants!$I$2:$I$369,D$1) -> 0 | E10: =SUM(B10:D10) -> 13
A11: Flagstone Manufactured Housing | B11: =COUNTIFS(Tenants!$C$2:$C$369,$A11,Tenants!$I$2:$I$369,B$1) -> 27 | C11: =COUNTIFS(Tenants!$C$2:$C$369,$A11,Tenants!$I$2:$I$369,C$1) -> 11 | D11: =COUNTIFS(Tenants!$C$2:$C$369,$A11,Tenants!$I$2:$I$369,D$1) -> 0 | E11: =SUM(B11:D11) -> 38
A12: Golden Gate Housing | B12: =COUNTIFS(Tenants!$C$2:$C$369,$A12,Tenants!$I$2:$I$369,B$1) -> 10 | C12: =COUNTIFS(Tenants!$C$2:$C$369,$A12,Tenants!$I$2:$I$369,C$1) -> 6 | D12: =COUNTIFS(Tenants!$C$2:$C$369,$A12,Tenants!$I$2:$I$369,D$1) -> 0 | E12: =SUM(B12:D12) -> 16
A13: Ocean Breeze ABNB | B13: =COUNTIFS(Tenants!$C$2:$C$369,$A13,Tenants!$I$2:$I$369,B$1) -> 1 | C13: =COUNTIFS(Tenants!$C$2:$C$369,$A13,Tenants!$I$2:$I$369,C$1) -> 7 | D13: =COUNTIFS(Tenants!$C$2:$C$369,$A13,Tenants!$I$2:$I$369,D$1) -> 0 | E13: =SUM(B13:D13) -> 8
... A19: Woodlands HOA | B19: =COUNTIFS(Tenants!$C$2:$C$369,$A19,Tenants!$I$2:$I$369,B$1) -> 15 | C19: =COUNTIFS(Tenants!$C$2:$C$369,$A19,Tenants!$I$2:$I$369,C$1) -> 0 | D19: =COUNTIFS(Tenants!$C$2:$C$369,$A19,Tenants!$I$2:$I$369,D$1) -> 0 | E19: =SUM(B19:D19) -> 15
A20: Total | B20: =SUM(B2:B19) -> 207 | C20: =SUM(C2:C19) -> 156 | D20: =SUM(D2:D19) -> 5 | E20: =SUM(E2:E19) -> 368
A22: Source: Rent Manager Tenant Register (class60), read 09/23/2026. Read-only export; no changes made in Rent Manager.

Sheet Tenants
A1: Name | B1: Account # | C1: Property | D1: Unit | E1: Lease Start | F1: Lease End | G1: Email | H1: Phone | I1: Status | J1: Flag
A2: Marcia Clark | B2: 1 | C2: Riverview Apartments | D2: 1 | E2: 45962 | F2: 46323 | G2: m.clark@email.com | H2: (513) 555-4223 | I2: Current
A3: Charlie Apegian | B3: 2 | C3: Wain Manor | D3: Wain | E3: 46204 | F3: 46566 | G3: c.apegian@email.com | H3: (703) 555-9342 | I3: Current
A4: Fred Gregory | B4: 3 | C4: Riverview Apartments | D4: 3 | E4: 45853 | F4: 46217 | G4: fredg@email.com | H4: (703) 555-1405 | I4: Past
A5: Gregory Klein | B5: 4 | C5: Riverview Apartments | D5: 4 | E5: 46023 | F5: 46384 | G5: gklein@email.com | H5: (513) 555-3378 | I5: Current
A6: Kate Welsh | B6: 5 | C6: Riverview Apartments | D6: 6 | E6: 45717 | F6: 46081 | G6: katewelsh@email.com | H6: (703) 555-1305 | I6: Past
A7: Scott Stein | B7: 6 | C7: Riverview Apartments | D7: 7 | E7: 45108 | F7: 45471 | G7: scott.stein@email.com | H7: (703) 555-3871 | I7: Past
A8: Meehee Lee | B8: 7 | C8: Riverview Apartments | D8: 9 | E8: 45992 | F8: 46354 | G8: smart202020@email.com | H8: (513) 555-6230 | I8: Current
A9: Randy Smith | B9: 8 | C9: Riverview Apartments | D9: 10 | E9: 45703 | F9: 46067 | G9: bestdadrandysmith@email.com | H9: (513) 555-6818 | I9: Past
A10: Thomas Randall | B10: 9 | C10: Riverview Apartments | D10: 11 | E10: 45839 | F10: 46201 | G10: thomasthetankrandall@email.com | H10: (513) 555-2442 | I10: Past
A11: Josh Kerr | B11: 10 | C11: Riverview Apartments | D11: 13 | E11: 45474 | F11: 45836 | G11: joshkerr@email.com | H11: (513) 555-6303 | I11: Past
A12: Rina Dutto | B12: 11 | C12: Riverview Apartments | D12: 14 (+1) | E12: 45992 | F12: 46354 | G12: rinadutto@email.com | H12: (513) 555-2783 | I12: Current
A13: Shannon Gregory | B13: 12 | C13: Riverview Apartments | D13: 16 | E13: 44910 | F13: 45274 | G13: sheilamarygrey@email.com | H13: (513) 555-1586 | I13: Past
A14: Tina Hatch | B14: 13 | C14: Riverview Apartments | D14: 17 | E14: 44866 | F14: 45227 | G14: tinahatchtheegg@email.com | H14: (513) 555-1187 | I14: Past
A15: Laura Villa | B15: 14 | C15: Riverview Apartments | D15: 19 | E15: 46174 | F15: 46535 | G15: lvilla@email.com | H15: (513) 555-9028 | I15: Current | J15: Court
A16: Melissa Yeager | B16: 15 | C16: Riverview Apartments | D16: 20 | E16: 45689 | F16: 46050 | G16: missyyeager@email.com | H16: (513) 555-2448 | I16: Past
A17: Mateo Angelini | B17: 16 | C17: Riverview Apartments | D17: 21 | E17: 46082 | F17: 46446 | G17: mateo@email.com | H17: (513) 555-2858 | I17: Current
A18: Walter Van | B18: 17 | C18: Riverview Apartments | D18: 22 | E18: 46204 | F18: 46566 | G18: waltvandelaar@email.com | H18: (513) 555-0314 | I18: Current
A19: Lisa Yang | B19: 18 | C19: Riverview Apartments | D19: 23 | E19: 46204 | F19: 46566 | G19: lisa@email.com | H19: (513) 555-3664 | I19: Current
A20: Roger Mandel | B20: 19 | C20: Riverview Apartments | D20: 24 (+1) | E20: 46296 | F20: 46658 | G20: coldcatchrodger@email.com | H20: (513) 555-5137 | I20: Current
A21: Najwa Kandil | B21: 20 | C21: Riverview Apartments | D21: 25 | E21: 46054 | F21: 46415 | G21: najwa@email.com | H21: (513) 555-4041 | I21: Current
A22: Sterling Maysfield | B22: 21 | C22: Riverview Apartments | D22: 26 | E22: 45197 | F22: 45563 | G22: maysfield@email.com | H22: (513) 555-8651 | I22: Past
A23: Jerry Vechio | B23: 22 | C23: Riverview Apartments | D23: 27 | E23: 46113 | F23: 46474 | G23: jerrythemanvechio@email.com | H23: (703) 555-8482 | I23: Current
A24: Justin Helterbrand | B24: 23 | C24: Riverview Apartments | D24: 28 | E24: 46204 | F24: 46566 | G24: johnnyboy1111@email.com | H24: (513) 555-0764 | I24: Current
A25: Lily Dalton | B25: 24 | C25: Riverview Apartments | D25: 30 | E25: 45108 | F25: 45471 | G25: dalton@email.com | H25: (513) 555-6743 | I25: Past
A26: Patrick O'Malley | B26: 49 | C26: Flagstone Manufactured Housing | D26: Lot #105 (+1) | E26: 45474 | F26: 45836 | G26: patrickomalley@email.com | H26: (513) 555-3004 | I26: Past
A27: Gretchen Rutter | B27: 50 | C27: Flagstone Manufactured Housing | D27: Lot #106 (+1) | E27: 45962 | F27: 46323 | G27: gretchenr@email.com | H27: (513) 555-8181 | I27: Current
... A48: Holly Mckenzie | B48: 72 | C48: 410-415 Southblock | D48: 415S | E48: 45413 | F48: 45775 | G48: hmakenzie@email.com | H48: (703) 555-9286 | I48: Past
A49: Gap, Inc. | B49: 73 | C49: Tri-County Mall | D49: 1 | E49: 44652 | F49: 46474 | G49: info@email.com | H49: 511-555-3620 | I49: Current | J49: Notice
A50: Game Stop | B50: 74 | C50: Tri-County Mall | D50: 2 | E50: 45597 | F50: 47420 | G50: info@email.com | H50: 511-555-8116 | I50: Current
A51: Getz Jewelers | B51: 75 | C51: Tri-County Mall | D51: 3 | E51: 45627 | F51: 46354 | G51: info@email.com | H51: 511-555-2223 | I51: Current
A52: American Eagle | B52: 76 | C52: Tri-County Mall | D52: 4 | E52: 46023 | F52: 47845 | G52: info@email.com | H52: 511-555-3693 | I52: Current
A53: Axel Green | B53: 77 | C53: Buckeye Hall | D53: A | E53: 44972 | F53: 45252 | G53: axelgreen@email.com | H53: 741-555-8924 | I53: Past
A54: Tyler Maxwell | B54: 78 | C54: Buckeye Hall | D54: B | E54: 44972 | F54: 45252 | G54: tylermaxwell@email.com | H54: (354) 555-7511 | I54: Past
A55: Clint Brewer | B55: 79 | C55: Buckeye Hall | D55: C | E55: 44972 | F55: 45252 | G55: clintbrewer@email.com | H55: 885-555-5321 | I55: Past
A56: Raymond Smith | B56: 80 | C56: Buckeye Hall | D56: D | E56: 44972 | F56: 45252 | G56: raysmith@email.com | H56: (731) 555-4711 | I56: Past
A57: Marlon Lucas | B57: 81 | C57: Buckeye Hall | D57: E | E57: 44972 | F57: 45252 | G57: marlonlucas@email.com | H57: (354) 555-1745 | I57: Past
A58: Alexander Briggs | B58: 82 | C58: Buckeye Hall | D58: F | E58: 44972 | F58: 45252 | G58: alexanderbriggs@email.com | H58: 545-555-7414 | I58: Past
A59: Steven Endres | B59: 83 | C59: Buckeye Hall | D59: H | E59: 44972 | F59: 45252 | G59: sendres@email.com | H59: (314) 555-1114 | I59: Past
A60: Maxime Rousseau | B60: 84 | C60: Buckeye Hall | D60: I | E60: 44972 | F60: 45252 | G60: mrousseau@email.com | H60: (314) 555-9741 | I60: Past
...
